{"nbformat_minor":2,"metadata":{"kernelspec":{"language":"swift","name":"swift","display_name":"Swift"},"language_info":{"name":"swift","mimetype":"text\/x-swift","version":"","file_extension":".swift"}},"cells":[{"metadata":{},"cell_type":"markdown","source":" ## Error Handling\n\n You represent errors using any type that adopts the `Error` protocol.\n\n"},{"execution_count":0,"source":"enum PrinterError: Error {\n    case outOfPaper\n    case noToner\n    case onFire\n}\n","cell_type":"code","metadata":{},"outputs":[]},{"metadata":{},"source":" Use `throw` to throw an error and `throws` to mark a function that can throw an error. If you throw an error in a function, the function returns immediately and the code that called the function handles the error.\n\n","cell_type":"markdown"},{"source":"func send(job: Int, toPrinter printerName: String) throws -> String {\n    if printerName == \"Never Has Toner\" {\n        throw PrinterError.noToner\n    }\n    return \"Job sent\"\n}\n","execution_count":0,"cell_type":"code","metadata":{},"outputs":[]},{"metadata":{},"source":" There are several ways to handle errors. One way is to use `do`-`catch`. Inside the `do` block, you mark code that can throw an error by writing `try` in front of it. Inside the `catch` block, the error is automatically given the name `error` unless you give it a different name.\n\n","cell_type":"markdown"},{"execution_count":0,"source":"do {\n    let printerResponse = try send(job: 1040, toPrinter: \"Bi Sheng\")\n    print(printerResponse)\n} catch {\n    print(error)\n}\n","cell_type":"code","outputs":[],"metadata":{}},{"metadata":{},"cell_type":"markdown","source":" - Experiment:\n Change the printer name to `\"Never Has Toner\"`, so that the `send(job:toPrinter:)` function throws an error.\n\n You can provide multiple `catch` blocks that handle specific errors. You write a pattern after `catch` just as you do after `case` in a switch.\n\n"},{"execution_count":0,"source":"do {\n    let printerResponse = try send(job: 1440, toPrinter: \"Gutenberg\")\n    print(printerResponse)\n} catch PrinterError.onFire {\n    print(\"I'll just put this over here, with the rest of the fire.\")\n} catch let printerError as PrinterError {\n    print(\"Printer error: \\(printerError).\")\n} catch {\n    print(error)\n}\n","cell_type":"code","metadata":{},"outputs":[]},{"metadata":{},"source":" - Experiment:\n Add code to throw an error inside the `do` block. What kind of error do you need to throw so that the error is handled by the first `catch` block? What about the second and third blocks?\n\n Another way to handle errors is to use `try?` to convert the result to an optional. If the function throws an error, the specific error is discarded and the result is `nil`. Otherwise, the result is an optional containing the value that the function returned.\n\n","cell_type":"markdown"},{"source":"let printerSuccess = try? send(job: 1884, toPrinter: \"Mergenthaler\")\nlet printerFailure = try? send(job: 1885, toPrinter: \"Never Has Toner\")\n","execution_count":0,"cell_type":"code","outputs":[],"metadata":{}},{"metadata":{},"source":" Use `defer` to write a block of code that is executed after all other code in the function, just before the function returns. The code is executed regardless of whether the function throws an error. You can use `defer` to write setup and cleanup code next to each other, even though they need to be executed at different times.\n\n","cell_type":"markdown"},{"execution_count":0,"source":"var fridgeIsOpen = false\nlet fridgeContent = [\"milk\", \"eggs\", \"leftovers\"]\nfunc fridgeContains(_ food: String) -> Bool {\n    fridgeIsOpen = true\n    defer {\n        fridgeIsOpen = false\n    }\n    let result = fridgeContent.contains(food)\n    return result\n}\nfridgeContains(\"banana\")\nprint(fridgeIsOpen)\n","cell_type":"code","outputs":[],"metadata":{}},{"metadata":{},"source":" [Previous](@previous) | [Next](@next)\n","cell_type":"markdown"}],"nbformat":4}